Workbook

Sheet PROCESI_Prioriteti
A1: TABLICA ODLUČIVANJA
B3: Financije | D3: Posao
B4: P | C4: B | D4: F | E4: T | F4: G | J4: PROCESI
A5: P1 | B5: 6 k | C5: 5 | D5: 4 | E5: 4.6 | F5: 7 | L5: popunjavamo
A6: P2 | B6: 5 k | C6: 6 | D6: 4 | E6: 4.2 | F6: 5
A7: P3 | B7: 7 k | C7: 3 | D7: 5 | E7: 3.2 | F7: 12 | J7: K | L7: K1 | N7: K2 | P7: K3 | R7: K4 | T7: K5 | V7: K6 | Y7: UP
L8: =PROCESIUsporedbaKriteriji!AE19 -> 0.20874704 | N8: =PROCESIUsporedbaKriteriji!AE20 -> 0.16591117 | P8: =PROCESIUsporedbaKriteriji!AE21 -> 0.2555546 | R8: =PROCESIUsporedbaKriteriji!AE22 -> 0.15390027 | T8: =PROCESIUsporedbaKriteriji!AE23 -> 0.050233523 | V8: =PROCESIUsporedbaKriteriji!AE24 -> 0.1656534
A9: TABLICA PRIORITETA | J9: U | K9: PK | L9: PK1.1 | M9: PK1.2 | N9: PK2.1 | O9: PK2.2 | P9: PK3.1 | Q9: PK3.2 | R9: PK4.1 | S9: PK4.2 | T9: PK5.1 | U9: PK5.2 | V9: PK6.1 | W9: PK6.2 | X9: PK6.3
L10: =PKFinancijskaUčinkovitost!P11 -> 0.61351179 | M10: =PKFinancijskaUčinkovitost!P12 -> 0.38648821 | N10: =PKKvalitetaTočnost!P11 -> 0.5 | O10: =PKKvalitetaTočnost!P12 -> 0.5 | P10: =PKUbrzanjeProcesa!P11 -> 0.55750667 | Q10: =PKUbrzanjeProcesa!P12 -> 0.44249333 | R10: =PKLjudskiResursi!P11 -> 0.61351179 | S10: =PKLjudskiResursi!P12 -> 0.38648821 | T10: =PKPoboljšanjeIskustva!P11 -> 0.53373742 | U10: =PKPoboljšanjeIskustva!P12 -> 0.46626258 | V10: =PKUtjecajNaOrgUčinkovitost!T15 -> 0.2157761 | W10: =PKUtjecajNaOrgUčinkovitost!T16 -> 0.53256163 | X10: =PKUtjecajNaOrgUčinkovitost!T17 -> 0.25166227
B11: Financije | D11: Posao | G11: UP | J11: P1 | L11: =TrošakProvedbeProcesa!T15 -> 0.44330345 | M11: =UštedaUOdnosuNaPrije!T15 -> 0.55051855 | N11: =TočnostPrikupljenihInfo!T15 -> 0.51288054 | O11: =OperativnePogreške!T15 -> 0.37050756 | P11: =TrajanjeProcesa!T15 -> 0.51430896 | Q11: =RazinaAutoRutinskihKoraka!T15 -> 0.16208762 | R11: =OpsegRučnihOperacija!T15 -> 0.34300713 | S11: =BrojPotrebnihLjudiPROCESI!T15 -> 0.29395129 | T11: =TransparentnostPostupaka!T15 -> 0.37592585 | U11: =KomunikacijaIPristupPodacima!T15 -> 0.40002126 | V11: =KoordinacijaIzmeđuOdjela!T15 -> 0.53703124 | W11: =AdministrativnoOpterećenje!T15 -> 0.56407897 | X11: =PraćenjeIKontorlaProcesa!T15 -> 0.260366 | Y11: =L$8*L$10*L11+L$8*M$10*M11+N$8*N$10*N11+N$8*O$10*O11+P$8*P$10*P11+P$8*Q$10*Q11+R$8*R$10*R11+R$8*S$10*S11+T$8*T$10*T11+T$8*U$10*U11+V$8*V$10*V11+V$8*W$10*W11+V$8*X$10*X11 -> 0.41520745
J12: P2 | L12: =TrošakProvedbeProcesa!T16 -> 0.41068315 | M12: =UštedaUOdnosuNaPrije!T16 -> 0.28629628 | N12: =TočnostPrikupljenihInfo!T16 -> 0.33519816 | O12: =OperativnePogreške!T16 -> 0.45057211 | P12: =TrajanjeProcesa!T16 -> 0.33156685 | Q12: =RazinaAutoRutinskihKoraka!T16 -> 0.3006598 | R12: =OpsegRučnihOperacija!T16 -> 0.39999379 | S12: =BrojPotrebnihLjudiPROCESI!T16 -> 0.53414495 | T12: =TransparentnostPostupaka!T16 -> 0.40306529 | U12: =KomunikacijaIPristupPodacima!T16 -> 0.47612861 | V12: =KoordinacijaIzmeđuOdjela!T16 -> 0.30998654 | W12: =AdministrativnoOpterećenje!T16 -> 0.31680936 | X12: =PraćenjeIKontorlaProcesa!T16 -> 0.40492095 | Y12: =L$8*L$10*L12+L$8*M$10*M12+N$8*N$10*N12+N$8*O$10*O12+P$8*P$10*P12+P$8*Q$10*Q12+R$8*R$10*R12+R$8*S$10*S12+T$8*T$10*T12+T$8*U$10*U12+V$8*V$10*V12+V$8*W$10*W12+V$8*X$10*X12 -> 0.36952319
B13: P | C13: B | D13: F | E13: T | F13: G | J13: P3 | L13: =TrošakProvedbeProcesa!T17 -> 0.1460134 | M13: =UštedaUOdnosuNaPrije!T17 -> 0.16318517 | N13: =TočnostPrikupljenihInfo!T17 -> 0.15192131 | O13: =OperativnePogreške!T17 -> 0.17892033 | P13: =TrajanjeProcesa!T17 -> 0.15412419 | Q13: =RazinaAutoRutinskihKoraka!T17 -> 0.53725258 | R13: =OpsegRučnihOperacija!T17 -> 0.25699908 | S13: =BrojPotrebnihLjudiPROCESI!T17 -> 0.17190376 | T13: =TransparentnostPostupaka!T17 -> 0.22100886 | U13: =KomunikacijaIPristupPodacima!T17 -> 0.12385013 | V13: =KoordinacijaIzmeđuOdjela!T17 -> 0.15298222 | W13: =AdministrativnoOpterećenje!T17 -> 0.11911166 | X13: =PraćenjeIKontorlaProcesa!T17 -> 0.33471305 | Y13: =L$8*L$10*L13+L$8*M$10*M13+N$8*N$10*N13+N$8*O$10*O13+P$8*P$10*P13+P$8*Q$10*Q13+R$8*R$10*R13+R$8*S$10*S13+T$8*T$10*T13+T$8*U$10*U13+V$8*V$10*V13+V$8*W$10*W13+V$8*X$10*X13 -> 0.21526935
A15: P1
A16: P2
A17: P3

Sheet PROCESI_AO
C4: AO | D4: PROMJENE | J4: PROCESI
C5: K1-0,05 | D5: NEMA
C6: K1+0,05 | D6: NEMA
C7: K2-0,05 | D7: NEMA | J7: K | L7: K1 | N7: K2 | P7: K3 | R7: K4 | T7: K5 | V7: K6 | Y7: UP
C8: K2+0,05 | D8: NEMA | L8: =PROCESIUsporedbaKriteriji!AE19 -> 0.20874704 | N8: =PROCESIUsporedbaKriteriji!AE20 -> 0.16591117 | P8: =PROCESIUsporedbaKriteriji!AE21 -> 0.2555546 | R8: =PROCESIUsporedbaKriteriji!AE22 -> 0.15390027 | T8: =PROCESIUsporedbaKriteriji!AE23 -> 0.050233523 | V8: =PROCESIUsporedbaKriteriji!AE24 -> 0.1656534
C9: K3-0,05 | D9: NEMA | J9: U | K9: PK | L9: PK1.1 | M9: PK1.2 | N9: PK2.1 | O9: PK2.2 | P9: PK3.1 | Q9: PK3.2 | R9: PK4.1 | S9: PK4.2 | T9: PK5.1 | U9: PK5.2 | V9: PK6.1 | W9: PK6.2 | X9: PK6.3
C10: K3+0,05 | D10: NEMA | L10: 0.61351179 | M10: 0.38648821 | N10: 0.5 | O10: 0.5 | P10: 0.55750667 | Q10: 0.44249333 | R10: 0.61351179 | S10: 0.38648821 | T10: 0.53373742 | U10: 0.46626258 | V10: 0.2157761 | W10: 0.53256163 | X10: 0.25166227
C11: K4-0,05 | D11: NEMA | J11: P1 | L11: 0.44330345 | M11: 0.55051855 | N11: 0.51288054 | O11: 0.37050756 | P11: 0.51430896 | Q11: 0.16208762 | R11: 0.34300713 | S11: 0.29395129 | T11: 0.37592585 | U11: 0.40002126 | V11: 0.53703124 | W11: 0.56407897 | X11: 0.260366 | Y11: =L$8*L$10*L11+L$8*M$10*M11+N$8*N$10*N11+N$8*O$10*O11+P$8*P$10*P11+P$8*Q$10*Q11+R$8*R$10*R11+R$8*S$10*S11+T$8*T$10*T11+T$8*U$10*U11+V$8*V$10*V11+V$8*W$10*W11+V$8*X$10*X11 -> 0.41520745 | Z11: 1.
C12: K4+0,05 | D12: NEMA | J12: P2 | L12: 0.41068315 | M12: 0.28629628 | N12: 0.33519816 | O12: 0.45057211 | P12: 0.33156685 | Q12: 0.3006598 | R12: 0.39999379 | S12: 0.53414495 | T12: 0.40306529 | U12: 0.47612861 | V12: 0.30998654 | W12: 0.31680936 | X12: 0.40492095 | Y12: =L$8*L$10*L12+L$8*M$10*M12+N$8*N$10*N12+N$8*O$10*O12+P$8*P$10*P12+P$8*Q$10*Q12+R$8*R$10*R12+R$8*S$10*S12+T$8*T$10*T12+T$8*U$10*U12+V$8*V$10*V12+V$8*W$10*W12+V$8*X$10*X12 -> 0.36952319 | Z12: 2.
C13: K5-0,05 | D13: NEMA | J13: P3 | L13: 0.1460134 | M13: 0.16318517 | N13: 0.15192131 | O13: 0.17892033 | P13: 0.15412419 | Q13: 0.53725258 | R13: 0.25699908 | S13: 0.17190376 | T13: 0.22100886 | U13: 0.12385013 | V13: 0.15298222 | W13: 0.11911166 | X13: 0.33471305 | Y13: =L$8*L$10*L13+L$8*M$10*M13+N$8*N$10*N13+N$8*O$10*O13+P$8*P$10*P13+P$8*Q$10*Q13+R$8*R$10*R13+R$8*S$10*S13+T$8*T$10*T13+T$8*U$10*U13+V$8*V$10*V13+V$8*W$10*W13+V$8*X$10*X13 -> 0.21526935 | Z13: 3.
C14: K5+0,05 | D14: NEMA
C15: K6-0,05 | D15: NEMA
C16: K6+0,05 | D16: NEMA
J18: AO: K1-0,05 | AE18: AO: K4-0,05
J19: K | L19: K1 | N19: K2 | P19: K3 | R19: K4 | T19: K5 | V19: K6 | Y19: UP | AE19: K | AG19: K1 | AI19: K2 | AK19: K3 | AM19: K4 | AO19: K5 | AQ19: K6 | AT19: UP
L20: =L8-0.05 -> 0.15874704 | N20: =N8+N8/(N8+P8+R8+T8+V8)*0.05 -> 0.17639524 | P20: =P8+P8/(N8+P8+R8+T8+V8)*0.05 -> 0.27170333 | R20: =R8+R8/(N8+P8+R8+T8+V8)*0.05 -> 0.16362537 | T20: =T8+T8/(N8+P8+R8+T8+V8)*0.05 -> 0.053407825 | V20: =V8+V8/(N8+P8+R8+T8+V8)*0.05 -> 0.17612119 | AG20: =L8+L8/(L8+N8+P8+T8+V8)*0.05 -> 0.22108288 | AI20: =N8+N8/(L8+N8+P8+T8+V8)*0.05 -> 0.17571563 | AK20: =P8+P8/(L8+P8+N8+T8+V8)*0.05 -> 0.27065652 | AM20: =R8-0.05 -> 0.10390027 | AO20: =T8+T8/(L8+P8+N8+T8+V8)*0.05 -> 0.053202058 | AQ20: =V8+V8/(L8+P8+N8+T8+V8)*0.05 -> 0.17544264
J21: U | K21: PK | L21: PK1.1 | M21: PK1.2 | N21: PK2.1 | O21: PK2.2 | P21: PK3.1 | Q21: PK3.2 | R21: PK4.1 | S21: PK4.2 | T21: PK5.1 | U21: PK5.2 | V21: PK6.1 | W21: PK6.2 | X21: PK6.3 | AE21: U | AF21: PK | AG21: PK1.1 | AH21: PK1.2 | AI21: PK2.1 | AJ21: PK2.2 | AK21: PK3.1 | AL21: PK3.2 | AM21: PK4.1 | AN21: PK4.2 | AO21: PK5.1 | AP21: PK5.2 | AQ21: PK6.1 | AR21: PK6.2 | AS21: PK6.3
L22: 0.61351179 | M22: 0.38648821 | N22: 0.5 | O22: 0.5 | P22: 0.55750667 | Q22: 0.44249333 | R22: 0.61351179 | S22: 0.38648821 | T22: 0.53373742 | U22: 0.46626258 | V22: 0.2157761 | W22: 0.53256163 | X22: 0.25166227 | AG22: 0.61351179 | AH22: 0.38648821 | AI22: 0.5 | AJ22: 0.5 | AK22: 0.55750667 | AL22: 0.44249333 | AM22: 0.61351179 | AN22: 0.38648821 | AO22: 0.53373742 | AP22: 0.46626258 | AQ22: 0.2157761 | AR22: 0.53256163 | AS22: 0.25166227
J23: P1 | L23: 0.44330345 | M23: 0.55051855 | N23: 0.51288054 | O23: 0.37050756 | P23: 0.51430896 | Q23: 0.16208762 | R23: 0.34300713 | S23: 0.29395129 | T23: 0.37592585 | U23: 0.40002126 | V23: 0.53703124 | W23: 0.56407897 | X23: 0.260366 | Y23: =L$20*L$22*L23+L$20*M$22*M23+N$20*N$22*N23+N$20*O$22*O23+P$20*P$22*P23+P$20*Q$22*Q23+R$20*R$22*R23+R$20*S$22*S23+T$20*T$22*T23+T$20*U$22*U23+V$20*V$22*V23+V$20*W$22*W23+V$20*X$22*X23 -> 0.41081358 | Z23: 1. | AE23: P1 | AG23: 0.44330345 | AH23: 0.55051855 | AI23: 0.51288054 | AJ23: 0.37050756 | AK23: 0.51430896 | AL23: 0.16208762 | AM23: 0.34300713 | AN23: 0.29395129 | AO23: 0.37592585 | AP23: 0.40002126 | AQ23: 0.53703124 | AR23: 0.56407897 | AS23: 0.260366 | AT23: =AG$20*AG$22*AG23+AG$20*AH$22*AH23+AI$20*AI$22*AI23+AI$20*AJ$22*AJ23+AK$20*AK$22*AK23+AK$20*AL$22*AL23+AM$20*AM$22*AM23+AM$20*AN$22*AN23+AO$20*AO$22*AO23+AO$20*AP$22*AP23+AQ$20*AQ$22*AQ23+AQ$20*AR$22*AR23+AQ$20*AS$22*AS23 -> 0.42059452 | AU23: 1
J24: P2 | L24: 0.41068315 | M24: 0.28629628 | N24: 0.33519816 | O24: 0.45057211 | P24: 0.33156685 | Q24: 0.3006598 | R24: 0.39999379 | S24: 0.53414495 | T24: 0.40306529 | U24: 0.47612861 | V24: 0.30998654 | W24: 0.31680936 | X24: 0.40492095 | Y24: =L$20*L$22*L24+L$20*M$22*M24+N$20*N$22*N24+N$20*O$22*O24+P$20*P$22*P24+P$20*Q$22*Q24+R$20*R$22*R24+R$20*S$22*S24+T$20*T$22*T24+T$20*U$22*U24+V$20*V$22*V24+V$20*W$22*W24+V$20*X$22*X24 -> 0.3699601 | Z24: 2. | AE24: P2 | AG24: 0.41068315 | AH24: 0.28629628 | AI24: 0.33519816 | AJ24: 0.45057211 | AK24: 0.33156685 | AL24: 0.3006598 | AM24: 0.39999379 | AN24: 0.53414495 | AO24: 0.40306529 | AP24: 0.47612861 | AQ24: 0.30998654 | AR24: 0.31680936 | AS24: 0.40492095 | AT24: =AG$20*AG$22*AG24+AG$20*AH$22*AH24+AI$20*AI$22*AI24+AI$20*AJ$22*AJ24+AK$20*AK$22*AK24+AK$20*AL$22*AL24+AM$20*AM$22*AM24+AM$20*AN$22*AN24+AO$20*AO$22*AO24+AO$20*AP$22*AP24+AQ$20*AQ$22*AQ24+AQ$20*AR$22*AR24+AQ$20*AS$22*AS24 -> 0.36465861 | AU24: 2
J25: P3 | L25: 0.1460134 | M25: 0.16318517 | N25: 0.15192131 | O25: 0.17892033 | P25: 0.15412419 | Q25: 0.53725258 | R25: 0.25699908 | S25: 0.17190376 | T25: 0.22100886 | U25: 0.12385013 | V25: 0.15298222 | W25: 0.11911166 | X25: 0.33471305 | Y25: =L$20*L$22*L25+L$20*M$22*M25+N$20*N$22*N25+N$20*O$22*O25+P$20*P$22*P25+P$20*Q$22*Q25+R$20*R$22*R25+R$20*S$22*S25+T$20*T$22*T25+T$20*U$22*U25+V$20*V$22*V25+V$20*W$22*W25+V$20*X$22*X25 -> 0.21922632 | Z25: 3. | AE25: P3 | AG25: 0.1460134 | AH25: 0.16318517 | AI25: 0.15192131 | AJ25: 0.17892033 | AK25: 0.15412419 | AL25: 0.53725258 | AM25: 0.25699908 | AN25: 0.17190376 | AO25: 0.22100886 | AP25: 0.12385013 | AQ25: 0.15298222 | AR25: 0.11911166 | AS25: 0.33471305 | AT25: =AG$20*AG$22*AG25+AG$20*AH$22*AH25+AI$20*AI$22*AI25+AI$20*AJ$22*AJ25+AK$20*AK$22*AK25+AK$20*AL$22*AL25+AM$20*AM$22*AM25+AM$20*AN$22*AN25+AO$20*AO$22*AO25+AO$20*AP$22*AP25+AQ$20*AQ$22*AQ25+AQ$20*AR$22*AR25+AQ$20*AS$22*AS25 -> 0.21474687 | AU25: 3
J29: AO: K1+0,05
J30: K | L30: K1 | N30: K2 | P30: K3 | R30: K4 | T30: K5 | V30: K6 | Y30: UP | AE30: AO:K4+0.05
L31: =L8+0.05 -> 0.25874704 | N31: =N8-N8/(N8+P8+R8+T8+V8)*0.05 -> 0.15542709 | P31: =P8-P8/(N8+P8+R8+T8+V8)*0.05 -> 0.23940587 | R31: =R8-R8/(N8+P8+R8+T8+V8)*0.05 -> 0.14417517 | T31: =T8-T8/(N8+P8+R8+T8+V8)*0.05 -> 0.047059221 | V31: =V8-V8/(N8+P8+R8+T8+V8)*0.05 -> 0.15518561 | AE31: K | AG31: K1 | AI31: K2 | AK31: K3 | AM31: K4 | AO31: K5 | AQ31: K6 | AT31: UP
J32: U | K32: PK | L32: PK1.1 | M32: PK1.2 | N32: PK2.1 | O32: PK2.2 | P32: PK3.1 | Q32: PK3.2 | R32: PK4.1 | S32: PK4.2 | T32: PK5.1 | U32: PK5.2 | V32: PK6.1 | W32: PK6.2 | X32: PK6.3 | AG32: =L8-L8/(L8+P8+N8+T8+V8)*0.05 -> 0.1964112 | AI32: =N8-N8/(L8+N8+P8+T8+V8)*0.05 -> 0.1561067 | AK32: =P8-P8/(L8+P8+N8+T8+V8)*0.05 -> 0.24045268 | AM32: =R8+0.05 -> 0.20390027 | AO32: =T8-T8/(L8+P8+N8+T8+V8)*0.05 -> 0.047264989 | AQ32: =V8-V8/(L8+P8+N8+T8+V8)*0.05 -> 0.15586416
L33: 0.61351179 | M33: 0.38648821 | N33: 0.5 | O33: 0.5 | P33: 0.55750667 | Q33: 0.44249333 | R33: 0.61351179 | S33: 0.38648821 | T33: 0.53373742 | U33: 0.46626258 | V33: 0.2157761 | W33: 0.53256163 | X33: 0.25166227 | AE33: U | AF33: PK | AG33: PK1.1 | AH33: PK1.2 | AI33: PK2.1 | AJ33: PK2.2 | AK33: PK3.1 | AL33: PK3.2 | AM33: PK4.1 | AN33: PK4.2 | AO33: PK5.1 | AP33: PK5.2 | AQ33: PK6.1 | AR33: PK6.2 | AS33: PK6.3
J34: P1 | L34: 0.44330345 | M34: 0.55051855 | N34: 0.51288054 | O34: 0.37050756 | P34: 0.51430896 | Q34: 0.16208762 | R34: 0.34300713 | S34: 0.29395129 | T34: 0.37592585 | U34: 0.40002126 | V34: 0.53703124 | W34: 0.56407897 | X34: 0.260366 | Y34: =L$31*L$33*L34+L$31*M$33*M34+N$31*N$33*N34+N$31*O$33*O34+P$31*P$33*P34+P$31*Q$33*Q34+R$31*R$33*R34+R$31*S$33*S34+T$31*T$33*T34+T$31*U$33*U34+V$31*V$33*V34+V$31*W$33*W34+V$31*X$33*X34 -> 0.41960133 | Z34: 1. | AG34: 0.61351179 | AH34: 0.38648821 | AI34: 0.5 | AJ34: 0.5 | AK34: 0.55750667 | AL34: 0.44249333 | AM34: 0.61351179 | AN34: 0.38648821 | AO34: 0.53373742 | AP34: 0.46626258 | AQ34: 0.2157761 | AR34: 0.53256163 | AS34: 0.25166227
J35: P2 | L35: 0.41068315 | M35: 0.28629628 | N35: 0.33519816 | O35: 0.45057211 | P35: 0.33156685 | Q35: 0.3006598 | R35: 0.39999379 | S35: 0.53414495 | T35: 0.40306529 | U35: 0.47612861 | V35: 0.30998654 | W35: 0.31680936 | X35: 0.40492095 | Y35: =L$31*L$33*L35+L$31*M$33*M35+N$31*N$33*N35+N$31*O$33*O35+P$31*P$33*P35+P$31*Q$33*Q35+R$31*R$33*R35+R$31*S$33*S35+T$31*T$33*T35+T$31*U$33*U35+V$31*V$33*V35+V$31*W$33*W35+V$31*X$33*X35 -> 0.36908628 | Z35: 2. | AE35: P1 | AG35: 0.44330345 | AH35: 0.55051855 | AI35: 0.51288054 | AJ35: 0.37050756 | AK35: 0.51430896 | AL35: 0.16208762 | AM35: 0.34300713 | AN35: 0.29395129 | AO35: 0.37592585 | AP35: 0.40002126 | AQ35: 0.53703124 | AR35: 0.56407897 | AS35: 0.260366 | AT35: =AG$32*AG$34*AG35+AG$32*AH$34*AH35+AI$32*AI$34*AI35+AI$32*AJ$34*AJ35+AK$32*AK$34*AK35+AK$32*AL$34*AL35+AM$32*AM$34*AM35+AM$32*AN$34*AN35+AO$32*AO$34*AO35+AO$32*AP$34*AP35+AQ$32*AQ$34*AQ35+AQ$32*AR$34*AR35+AQ$32*AS$34*AS35 -> 0.40982039 | AU35: 1
J36: P3 | L36: 0.1460134 | M36: 0.16318517 | N36: 0.15192131 | O36: 0.17892033 | P36: 0.15412419 | Q36: 0.53725258 | R36: 0.25699908 | S36: 0.17190376 | T36: 0.22100886 | U36: 0.12385013 | V36: 0.15298222 | W36: 0.11911166 | X36: 0.33471305 | Y36: =L$31*L$33*L36+L$31*M$33*M36+N$31*N$33*N36+N$31*O$33*O36+P$31*P$33*P36+P$31*Q$33*Q36+R$31*R$33*R36+R$31*S$33*S36+T$31*T$33*T36+T$31*U$33*U36+V$31*V$33*V36+V$31*W$33*W36+V$31*X$33*X36 -> 0.21131238 | Z36: 3. | AE36: P2 | AG36: 0.41068315 | AH36: 0.28629628 | AI36: 0.33519816 | AJ36: 0.45057211 | AK36: 0.33156685 | AL36: 0.3006598 | AM36: 0.39999379 | AN36: 0.53414495 | AO36: 0.40306529 | AP36: 0.47612861 | AQ36: 0.30998654 | AR36: 0.31680936 | AS36: 0.40492095 | AT36: =AG$32*AG$34*AG36+AG$32*AH$34*AH36+AI$32*AI$34*AI36+AI$32*AJ$34*AJ36+AK$32*AK$34*AK36+AK$32*AL$34*AL36+AM$32*AM$34*AM36+AM$32*AN$34*AN36+AO$32*AO$34*AO36+AO$32*AP$34*AP36+AQ$32*AQ$34*AQ36+AQ$32*AR$34*AR36+AQ$32*AS$34*AS36 -> 0.37438777 | AU36: 2
AE37: P3 | AG37: 0.1460134 | AH37: 0.16318517 | AI37: 0.15192131 | AJ37: 0.17892033 | AK37: 0.15412419 | AL37: 0.53725258 | AM37: 0.25699908 | AN37: 0.17190376 | AO37: 0.22100886 | AP37: 0.12385013 | AQ37: 0.15298222 | AR37: 0.11911166 | AS37: 0.33471305 | AT37: =AG$32*AG$34*AG37+AG$32*AH$34*AH37+AI$32*AI$34*AI37+AI$32*AJ$34*AJ37+AK$32*AK$34*AK37+AK$32*AL$34*AL37+AM$32*AM$34*AM37+AM$32*AN$34*AN37+AO$32*AO$34*AO37+AO$32*AP$34*AP37+AQ$32*AQ$34*AQ37+AQ$32*AR$34*AR37+AQ$32*AS$34*AS37 -> 0.21579183 | AU37: 3
J41: AO: K2-0,05 | AE41: AO:K5-0.05
J42: K | L42: K1 | N42: K2 | P42: K3 | R42: K4 | T42: K5 | V42: K6 | Y42: UP | AE42: K | AG42: K1 | AI42: K2 | AK42: K3 | AM42: K4 | AO42: K5 | AQ42: K6 | AT42: UP
L43: =L8+L8/(L8+P8+R8+T8+V8)*0.05 -> 0.22126052 | N43: =N8-0.05 -> 0.11591117 | P43: =P8+P8/(L8+P8+R8+T8+V8)*0.05 -> 0.27087399 | R43: =R8+R8/(L8+P8+R8+T8+V8)*0.05 -> 0.16312592 | T43: =T8+T8/(L8+P8+R8+T8+V8)*0.05 -> 0.053244804 | V43: =V8+V8/(L8+P8+R8+T8+V8)*0.05 -> 0.1755836 | AG43: =L8+L8/(L8+P8+N8+R8+V8)*0.05 -> 0.21973643 | AI43: =N8+N8/(L8+P8+N8+R8+V8)*0.05 -> 0.17464548 | AK43: =P8+P8/(L8+P8+N8+R8+V8)*0.05 -> 0.26900815 | AM43: =R8+R8/(L8+P8+N8+R8+V8)*0.05 -> 0.16200227 | AO43: =T8-0.05 -> 0.00023352311 | AQ43: =V8+V8/(L8+P8+N8+R8+V8)*0.05 -> 0.17437414
J44: U | K44: PK | L44: PK1.1 | M44: PK1.2 | N44: PK2.1 | O44: PK2.2 | P44: PK3.1 | Q44: PK3.2 | R44: PK4.1 | S44: PK4.2 | T44: PK5.1 | U44: PK5.2 | V44: PK6.1 | W44: PK6.2 | X44: PK6.3 | AE44: U | AF44: PK | AG44: PK1.1 | AH44: PK1.2 | AI44: PK2.1 | AJ44: PK2.2 | AK44: PK3.1 | AL44: PK3.2 | AM44: PK4.1 | AN44: PK4.2 | AO44: PK5.1 | AP44: PK5.2 | AQ44: PK6.1 | AR44: PK6.2 | AS44: PK6.3
L45: 0.61351179 | M45: 0.38648821 | N45: 0.5 | O45: 0.5 | P45: 0.55750667 | Q45: 0.44249333 | R45: 0.61351179 | S45: 0.38648821 | T45: 0.53373742 | U45: 0.46626258 | V45: 0.2157761 | W45: 0.53256163 | X45: 0.25166227 | AG45: 0.61351179 | AH45: 0.38648821 | AI45: 0.5 | AJ45: 0.5 | AK45: 0.55750667 | AL45: 0.44249333 | AM45: 0.61351179 | AN45: 0.38648821 | AO45: 0.53373742 | AP45: 0.46626258 | AQ45: 0.2157761 | AR45: 0.53256163 | AS45: 0.25166227
J46: P1 | L46: 0.44330345 | M46: 0.55051855 | N46: 0.51288054 | O46: 0.37050756 | P46: 0.51430896 | Q46: 0.16208762 | R46: 0.34300713 | S46: 0.29395129 | T46: 0.37592585 | U46: 0.40002126 | V46: 0.53703124 | W46: 0.56407897 | X46: 0.260366 | Y46: =L$43*L$45*L46+L$43*M$45*M46+N$43*N$45*N46+N$43*O$45*O46+P$43*P$45*P46+P$43*Q$45*Q46+R$43*R$45*R46+R$43*S$45*S46+T$43*T$45*T46+T$43*U$45*U46+V$43*V$45*V46+V$43*W$45*W46+V$43*X$45*X46 -> 0.4136197 | Z46: 1. | AE46: P1 | AG46: 0.44330345 | AH46: 0.55051855 | AI46: 0.51288054 | AJ46: 0.37050756 | AK46: 0.51430896 | AL46: 0.16208762 | AM46: 0.34300713 | AN46: 0.29395129 | AO46: 0.37592585 | AP46: 0.40002126 | AQ46: 0.53703124 | AR46: 0.56407897 | AS46: 0.260366 | AT46: =AG$43*AG$45*AG46+AG$43*AH$45*AH46+AI$43*AI$45*AI46+AI$43*AJ$45*AJ46+AK$43*AK$45*AK46+AK$43*AL$45*AL46+AM$43*AM$45*AM46+AM$43*AN$45*AN46+AO$43*AO$45*AO46+AO$43*AP$45*AP46+AQ$43*AQ$45*AQ46+AQ$43*AR$45*AR46+AQ$43*AS$45*AS46 -> 0.41668397 | AU46: 1
J47: P2 | L47: 0.41068315 | M47: 0.28629628 | N47: 0.33519816 | O47: 0.45057211 | P47: 0.33156685 | Q47: 0.3006598 | R47: 0.39999379 | S47: 0.53414495 | T47: 0.40306529 | U47: 0.47612861 | V47: 0.30998654 | W47: 0.31680936 | X47: 0.40492095 | Y47: =L$43*L$45*L47+L$43*M$45*M47+N$43*N$45*N47+N$43*O$45*O47+P$43*P$45*P47+P$43*Q$45*Q47+R$43*R$45*R47+R$43*S$45*S47+T$43*T$45*T47+T$43*U$45*U47+V$43*V$45*V47+V$43*W$45*W47+V$43*X$45*X47 -> 0.36812274 | Z47: 2. | AE47: P2 | AG47: 0.41068315 | AH47: 0.28629628 | AI47: 0.33519816 | AJ47: 0.45057211 | AK47: 0.33156685 | AL47: 0.3006598 | AM47: 0.39999379 | AN47: 0.53414495 | AO47: 0.40306529 | AP47: 0.47612861 | AQ47: 0.30998654 | AR47: 0.31680936 | AS47: 0.40492095 | AT47: =AG$43*AG$45*AG47+AG$43*AH$45*AH47+AI$43*AI$45*AI47+AI$43*AJ$45*AJ47+AK$43*AK$45*AK47+AK$43*AL$45*AL47+AM$43*AM$45*AM47+AM$43*AN$45*AN47+AO$43*AO$45*AO47+AO$43*AP$45*AP47+AQ$43*AQ$45*AQ47+AQ$43*AR$45*AR47+AQ$43*AS$45*AS47 -> 0.36596396 | AU47: 2
J48: P3 | L48: 0.1460134 | M48: 0.16318517 | N48: 0.15192131 | O48: 0.17892033 | P48: 0.15412419 | Q48: 0.53725258 | R48: 0.25699908 | S48: 0.17190376 | T48: 0.22100886 | U48: 0.12385013 | V48: 0.15298222 | W48: 0.11911166 | X48: 0.33471305 | Y48: =L$43*L$45*L48+L$43*M$45*M48+N$43*N$45*N48+N$43*O$45*O48+P$43*P$45*P48+P$43*Q$45*Q48+R$43*R$45*R48+R$43*S$45*S48+T$43*T$45*T48+T$43*U$45*U48+V$43*V$45*V48+V$43*W$45*W48+V$43*X$45*X48 -> 0.21825756 | Z48: 3. | AE48: P3 | AG48: 0.1460134 | AH48: 0.16318517 | AI48: 0.15192131 | AJ48: 0.17892033 | AK48: 0.15412419 | AL48: 0.53725258 | AM48: 0.25699908 | AN48: 0.17190376 | AO48: 0.22100886 | AP48: 0.12385013 | AQ48: 0.15298222 | AR48: 0.11911166 | AS48: 0.33471305 | AT48: =AG$43*AG$45*AG48+AG$43*AH$45*AH48+AI$43*AI$45*AI48+AI$43*AJ$45*AJ48+AK$43*AK$45*AK48+AK$43*AL$45*AL48+AM$43*AM$45*AM48+AM$43*AN$45*AN48+AO$43*AO$45*AO48+AO$43*AP$45*AP48+AQ$43*AQ$45*AQ48+AQ$43*AR$45*AR48+AQ$43*AS$45*AS48 -> 0.21735207 | AU48: 3
J53: AO: K2+0,05 | AE53: AO:K5+0.05
J54: K | L54: K1 | N54: K2 | P54: K3 | R54: K4 | T54: K5 | V54: K6 | Y54: UP | AE54: K | AG54: K1 | AI54: K2 | AK54: K3 | AM54: K4 | AO54: K5 | AQ54: K6 | AT54: UP
...

Sheet PROCESIUsporedbaKriteriji
C2: =B3 -> financije | D2: =B4 -> kvaliteta | E2: =B5 -> brzina | F2: =B6 -> ljudi | G2: =B7 -> korisnik | H2: =B8 -> učinkovitost | K2: =J3 -> financije | L2: =J4 -> kvaliteta | M2: =J5 -> brzina | N2: =J6 -> ljudi | O2: =J7 -> korisnik | P2: =J8 -> učinkovitost | S2: =R3 -> financije | T2: =R4 -> kvaliteta | U2: =R5 -> brzina | V2: =R6 -> ljudi | W2: =R7 -> korisnik | X2: =R8 -> učikovitost | AA2: =Z3 -> financije | AB2: =Z4 -> kvaliteta | AC2: =Z5 -> brzina | AD2: =Z6 -> ljudi | AE2: =Z7 -> korisnik | AF2: =Z8 -> učinkovitost
B3: financije | C3: 1 | D3: 3 | E3: 2 | F3: 2 | G3: 5 | H3: 3 | J3: financije | K3: 1 | L3: 1 | M3: =1/3 -> 0.33333333 | N3: 2 | O3: 4 | P3: =1/2 -> 0.5 | R3: financije | S3: 1 | T3: =1/2 -> 0.5 | U3: 1 | V3: 2 | W3: 3 | X3: =1/3 -> 0.33333333 | Z3: financije | AA3: =GEOMEAN(C3,K3,S3) -> 1 | AB3: =GEOMEAN(D3,L3,T3) -> 1.1447142 | AC3: =GEOMEAN(E3,M3,U3) -> 0.87358046 | AD3: =GEOMEAN(F3,N3,V3) -> 2 | AE3: =GEOMEAN(G3,O3,W3) -> 3.9148676 | AF3: =GEOMEAN(H3,P3,X3) -> 0.79370053
B4: kvaliteta | C4: =1/3 -> 0.33333333 | D4: 1 | E4: =1/2 -> 0.5 | F4: =1/2 -> 0.5 | G4: 3 | H4: 1 | J4: kvaliteta | K4: 1 | L4: 1 | M4: =1/5 -> 0.2 | N4: 1 | O4: 3 | P4: =1/3 -> 0.33333333 | R4: kvaliteta | S4: 2 | T4: 1 | U4: 2 | V4: 3 | W4: 5 | X4: 2 | Z4: kvaliteta | AA4: =GEOMEAN(C4,K4,S4) -> 0.87358046 | AB4: =GEOMEAN(D4,L4,T4) -> 1 | AC4: =GEOMEAN(E4,M4,U4) -> 0.58480355 | AD4: =GEOMEAN(F4,N4,V4) -> 1.1447142 | AE4: =GEOMEAN(G4,O4,W4) -> 3.5568933 | AF4: =GEOMEAN(H4,P4,X4) -> 0.87358046
B5: brzina | C5: =1/2 -> 0.5 | D5: 2 | E5: 1 | F5: 1 | G5: 4 | H5: 2 | J5: brzina | K5: 3 | L5: 2 | M5: 1 | N5: 3 | O5: 6 | P5: 2 | R5: brzina | S5: 1 | T5: =1/2 -> 0.5 | U5: 1 | V5: 2 | W5: 4 | X5: 2 | Z5: brzina | AA5: =GEOMEAN(C5,K5,S5) -> 1.1447142 | AB5: =GEOMEAN(D5,L5,T5) -> 1.259921 | AC5: =GEOMEAN(E5,M5,U5) -> 1 | AD5: =GEOMEAN(F5,N5,V5) -> 1.8171206 | AE5: =GEOMEAN(G5,O5,W5) -> 4.578857 | AF5: =GEOMEAN(H5,P5,X5) -> 2
B6: ljudi | C6: =1/2 -> 0.5 | D6: 2 | E6: 1 | F6: 1 | G6: 4 | H6: 2 | J6: ljudi | K6: =1/2 -> 0.5 | L6: 1 | M6: =1/3 -> 0.33333333 | N6: 1 | O6: 3 | P6: =1/2 -> 0.5 | R6: ljudi | S6: =1/2 -> 0.5 | T6: =1/3 -> 0.33333333 | U6: =1/2 -> 0.5 | V6: 1 | W6: 2 | X6: 3 | Z6: ljudi | AA6: =GEOMEAN(C6,K6,S6) -> 0.5 | AB6: =GEOMEAN(D6,L6,T6) -> 0.87358046 | AC6: =GEOMEAN(E6,M6,U6) -> 0.55032121 | AD6: =GEOMEAN(F6,N6,V6) -> 1 | AE6: =GEOMEAN(G6,O6,W6) -> 2.8844991 | AF6: =GEOMEAN(H6,P6,X6) -> 1.4422496
B7: korisnik | C7: =1/5 -> 0.2 | D7: =1/3 -> 0.33333333 | E7: =1/4 -> 0.25 | F7: =1/4 -> 0.25 | G7: 1 | H7: =1/3 -> 0.33333333 | J7: korisnik | K7: =1/4 -> 0.25 | L7: =1/3 -> 0.33333333 | M7: =1/6 -> 0.16666667 | N7: =1/3 -> 0.33333333 | O7: 1 | P7: =1/5 -> 0.2 | R7: korisnik | S7: =1/3 -> 0.33333333 | T7: =1/5 -> 0.2 | U7: =1/4 -> 0.25 | V7: =1/2 -> 0.5 | W7: 1 | X7: =1/4 -> 0.25 | Z7: korisnik | AA7: =GEOMEAN(C7,K7,S7) -> 0.25543648 | AB7: =GEOMEAN(D7,L7,T7) -> 0.28114422 | AC7: =GEOMEAN(E7,M7,U7) -> 0.21839512 | AD7: =GEOMEAN(F7,N7,V7) -> 0.34668064 | AE7: =GEOMEAN(G7,O7,W7) -> 1 | AF7: =GEOMEAN(H7,P7,X7) -> 0.25543648
B8: učinkovitost | C8: =1/3 -> 0.33333333 | D8: 1 | E8: =1/2 -> 0.5 | F8: =1/2 -> 0.5 | G8: 3 | H8: 1 | J8: učinkovitost | K8: 2 | L8: 3 | M8: =1/2 -> 0.5 | N8: 2 | O8: 5 | P8: 1 | R8: učikovitost | S8: 3 | T8: =1/5 -> 0.2 | U8: =1/2 -> 0.5 | V8: =1/3 -> 0.33333333 | W8: 4 | X8: 1 | Z8: učinkovitost | AA8: =GEOMEAN(C8,K8,S8) -> 1.259921 | AB8: =GEOMEAN(D8,L8,T8) -> 0.84343267 | AC8: =GEOMEAN(E8,M8,U8) -> 0.5 | AD8: =GEOMEAN(F8,N8,V8) -> 0.69336127 | AE8: =GEOMEAN(G8,O8,W8) -> 3.9148676 | AF8: =GEOMEAN(H8,P8,X8) -> 1
C10: =SUM(C3:C8) -> 2.8666667 | D10: =SUM(D3:D8) -> 9.3333333 | E10: =SUM(E3:E8) -> 5.25 | F10: =SUM(F3:F8) -> 5.25 | G10: =SUM(G3:G8) -> 20 | H10: =SUM(H3:H8) -> 9.3333333 | K10: =SUM(K3:K8) -> 7.75 | L10: =SUM(L3:L8) -> 8.3333333 | M10: =SUM(M3:M8) -> 2.5333333 | N10: =SUM(N3:N8) -> 9.3333333 | O10: =SUM(O3:O8) -> 22 | P10: =SUM(P3:P8) -> 4.5333333 | S10: =SUM(S3:S8) -> 7.8333333 | T10: =SUM(T3:T8) -> 2.7333333 | U10: =SUM(U3:U8) -> 5.25 | V10: =SUM(V3:V8) -> 8.8333333 | W10: =SUM(W3:W8) -> 19 | X10: =SUM(X3:X8) -> 8.5833333 | AA10: =SUM(AA3:AA8) -> 5.0336522 | AB10: =SUM(AB3:AB8) -> 5.4027926 | AC10: =SUM(AC3:AC8) -> 3.7271003 | AD10: =SUM(AD3:AD8) -> 7.0018767 | AE10: =SUM(AE3:AE8) -> 19.849985 | AF10: =SUM(AF3:AF8) -> 6.364967
C12: =C3/C$10 -> 0.34883721 | D12: =D3/D$10 -> 0.32142857 | E12: =E3/E$10 -> 0.38095238 | F12: =F3/F$10 -> 0.38095238 | G12: =G3/G$10 -> 0.25 | H12: =H3/H$10 -> 0.32142857 | K12: =K3/K$10 -> 0.12903226 | L12: =L3/L$10 -> 0.12 | M12: =M3/M$10 -> 0.13157895 | N12: =N3/N$10 -> 0.21428571 | O12: =O3/O$10 -> 0.18181818 | P12: =P3/P$10 -> 0.11029412 | S12: =S3/S$10 -> 0.12765957 | T12: =T3/T$10 -> 0.18292683 | U12: =U3/U$10 -> 0.19047619 | V12: =V3/V$10 -> 0.22641509 | W12: =W3/W$10 -> 0.15789474 | X12: =X3/X$10 -> 0.038834951 | AA12: =AA3/AA$10 -> 0.19866291 | AB12: =AB3/AB$10 -> 0.21187455 | AC12: =AC3/AC$10 -> 0.23438609 | AD12: =AD3/AD$10 -> 0.2856377 | AE12: =AE3/AE$10 -> 0.1972227 | AF12: =AF3/AF$10 -> 0.12469829
C13: =C4/C$10 -> 0.11627907 | D13: =D4/D$10 -> 0.10714286 | E13: =E4/E$10 -> 0.095238095 | F13: =F4/F$10 -> 0.095238095 | G13: =G4/G$10 -> 0.15 | H13: =H4/H$10 -> 0.10714286 | K13: =K4/K$10 -> 0.12903226 | L13: =L4/L$10 -> 0.12 | M13: =M4/M$10 -> 0.078947368 | N13: =N4/N$10 -> 0.10714286 | O13: =O4/O$10 -> 0.13636364 | P13: =P4/P$10 -> 0.073529412 | S13: =S4/S$10 -> 0.25531915 | T13: =T4/T$10 -> 0.36585366 | U13: =U4/U$10 -> 0.38095238 | V13: =V4/V$10 -> 0.33962264 | W13: =W4/W$10 -> 0.26315789 | X13: =X4/X$10 -> 0.23300971 | AA13: =AA4/AA$10 -> 0.17354804 | AB13: =AB4/AB$10 -> 0.18508946 | AC13: =AC4/AC$10 -> 0.15690577 | AD13: =AD4/AD$10 -> 0.16348677 | AE13: =AE4/AE$10 -> 0.17918872 | AF13: =AF4/AF$10 -> 0.13724823
C14: =C5/C$10 -> 0.1744186 | D14: =D5/D$10 -> 0.21428571 | E14: =E5/E$10 -> 0.19047619 | F14: =F5/F$10 -> 0.19047619 | G14: =G5/G$10 -> 0.2 | H14: =H5/H$10 -> 0.21428571 | K14: =K5/K$10 -> 0.38709677 | L14: =L5/L$10 -> 0.24 | M14: =M5/M$10 -> 0.39473684 | N14: =N5/N$10 -> 0.32142857 | O14: =O5/O$10 -> 0.27272727 | P14: =P5/P$10 -> 0.44117647 | S14: =S5/S$10 -> 0.12765957 | T14: =T5/T$10 -> 0.18292683 | U14: =U5/U$10 -> 0.19047619 | V14: =V5/V$10 -> 0.22641509 | W14: =W5/W$10 -> 0.21052632 | X14: =X5/X$10 -> 0.23300971 | AA14: =AA5/AA$10 -> 0.22741226 | AB14: =AB5/AB$10 -> 0.23319811 | AC14: =AC5/AC$10 -> 0.26830509 | AD14: =AD5/AD$10 -> 0.25951908 | AE14: =AE5/AE$10 -> 0.23067307 | AF14: =AF5/AF$10 -> 0.31422001
C15: =C6/C$10 -> 0.1744186 | D15: =D6/D$10 -> 0.21428571 | E15: =E6/E$10 -> 0.19047619 | F15: =F6/F$10 -> 0.19047619 | G15: =G6/G$10 -> 0.2 | H15: =H6/H$10 -> 0.21428571 | K15: =K6/K$10 -> 0.064516129 | L15: =L6/L$10 -> 0.12 | M15: =M6/M$10 -> 0.13157895 | N15: =N6/N$10 -> 0.10714286 | O15: =O6/O$10 -> 0.13636364 | P15: =P6/P$10 -> 0.11029412 | S15: =S6/S$10 -> 0.063829787 | T15: =T6/T$10 -> 0.12195122 | U15: =U6/U$10 -> 0.095238095 | V15: =V6/V$10 -> 0.11320755 | W15: =W6/W$10 -> 0.10526316 | X15: =X6/X$10 -> 0.34951456 | AA15: =AA6/AA$10 -> 0.099331455 | AB15: =AB6/AB$10 -> 0.16169054 | AC15: =AC6/AC$10 -> 0.14765398 | AD15: =AD6/AD$10 -> 0.14281885 | AE15: =AE6/AE$10 -> 0.14531493 | AF15: =AF6/AF$10 -> 0.22659184
C16: =C7/C$10 -> 0.069767442 | D16: =D7/D$10 -> 0.035714286 | E16: =E7/E$10 -> 0.047619048 | F16: =F7/F$10 -> 0.047619048 | G16: =G7/G$10 -> 0.05 | H16: =H7/H$10 -> 0.035714286 | K16: =K7/K$10 -> 0.032258065 | L16: =L7/L$10 -> 0.04 | M16: =M7/M$10 -> 0.065789474 | N16: =N7/N$10 -> 0.035714286 | O16: =O7/O$10 -> 0.045454545 | P16: =P7/P$10 -> 0.044117647 | S16: =S7/S$10 -> 0.042553191 | T16: =T7/T$10 -> 0.073170732 | U16: =U7/U$10 -> 0.047619048 | V16: =V7/V$10 -> 0.056603774 | W16: =W7/W$10 -> 0.052631579 | X16: =X7/X$10 -> 0.029126214 | AA16: =AA7/AA$10 -> 0.050745754 | AB16: =AB7/AB$10 -> 0.052036834 | AC16: =AC7/AC$10 -> 0.058596522 | AD16: =AD7/AD$10 -> 0.049512531 | AE16: =AE7/AE$10 -> 0.050377873 | AF16: =AF7/AF$10 -> 0.040131626
C17: =C8/C$10 -> 0.11627907 | D17: =D8/D$10 -> 0.10714286 | E17: =E8/E$10 -> 0.095238095 | F17: =F8/F$10 -> 0.095238095 | G17: =G8/G$10 -> 0.15 | H17: =H8/H$10 -> 0.10714286 | K17: =K8/K$10 -> 0.25806452 | L17: =L8/L$10 -> 0.36 | M17: =M8/M$10 -> 0.19736842 | N17: =N8/N$10 -> 0.21428571 | O17: =O8/O$10 -> 0.22727273 | P17: =P8/P$10 -> 0.22058824 | S17: =S8/S$10 -> 0.38297872 | T17: =T8/T$10 -> 0.073170732 | U17: =U8/U$10 -> 0.095238095 | V17: =V8/V$10 -> 0.037735849 | W17: =W8/W$10 -> 0.21052632 | X17: =X8/X$10 -> 0.11650485 | AA17: =AA8/AA$10 -> 0.25029958 | AB17: =AB8/AB$10 -> 0.1561105 | AC17: =AC8/AC$10 -> 0.13415255 | AD17: =AD8/AD$10 -> 0.099025061 | AE17: =AE8/AE$10 -> 0.1972227 | AF17: =AF8/AF$10 -> 0.15711
F19: =B3 -> financije | G19: =AVERAGE(C12:H12) -> 0.33393319 | N19: =J3 -> financije | O19: =AVERAGE(K12:P12) -> 0.14783487 | V19: =R3 -> financije | W19: =AVERAGE(S12:X12) -> 0.15403456 | AD19: =Z3 -> financije | AE19: =AVERAGE(AA12:AF12) -> 0.20874704
F20: =B4 -> kvaliteta | G20: =AVERAGE(C13:H13) -> 0.11184016 | N20: =J4 -> kvaliteta | O20: =AVERAGE(K13:P13) -> 0.10750259 | V20: =R4 -> kvaliteta | W20: =AVERAGE(S13:X13) -> 0.30631924 | AD20: =Z4 -> kvaliteta | AE20: =AVERAGE(AA13:AF13) -> 0.16591117
F21: =B5 -> brzina | G21: =AVERAGE(C14:H14) -> 0.19732374 | N21: =J5 -> brzina | O21: =AVERAGE(K14:P14) -> 0.34286099 | V21: =R5 -> brzina | W21: =AVERAGE(S14:X14) -> 0.19516895 | AD21: =Z5 -> brzina | AE21: =AVERAGE(AA14:AF14) -> 0.2555546
F22: =B6 -> ljudi | G22: =AVERAGE(C15:H15) -> 0.19732374 | N22: =J6 -> ljudi | O22: =AVERAGE(K15:P15) -> 0.11164928 | V22: =R6 -> ljudi | W22: =AVERAGE(S15:X15) -> 0.14150073 | AD22: =Z6 -> ljudi | AE22: =AVERAGE(AA15:AF15) -> 0.15390027
F23: =B7 -> korisnik | G23: =AVERAGE(C16:H16) -> 0.047739018 | N23: =J7 -> korisnik | O23: =AVERAGE(K16:P16) -> 0.043889003 | V23: =R7 -> korisnik | W23: =AVERAGE(S16:X16) -> 0.050284089 | AD23: =Z7 -> korisnik | AE23: =AVERAGE(AA16:AF16) -> 0.050233523
F24: =B8 -> učinkovitost | G24: =AVERAGE(C17:H17) -> 0.11184016 | N24: =J8 -> učinkovitost | O24: =AVERAGE(K17:P17) -> 0.24626327 | V24: =R8 -> učikovitost | W24: =AVERAGE(S17:X17) -> 0.15269243 | AD24: =Z8 -> učinkovitost | AE24: =AVERAGE(AA17:AF17) -> 0.1656534
C26: =C3*G$19 -> 0.33393319 | D26: =D3*G$20 -> 0.33552049 | E26: =E3*G$21 -> 0.39464747 | F26: =F3*G$22 -> 0.39464747 | G26: =G3*G$23 -> 0.23869509 | H26: =G$24*H3 -> 0.33552049 | K26: =K3*O$19 -> 0.14783487 | L26: =L3*O$20 -> 0.10750259 | M26: =M3*O$21 -> 0.114287 | N26: =N3*O$22 -> 0.22329856 | O26: =O3*O$23 -> 0.17555601 | P26: =O$24*P3 -> 0.12313163 | S26: =S3*W$19 -> 0.15403456 | T26: =T3*W$20 -> 0.15315962 | U26: =U3*W$21 -> 0.19516895 | V26: =V3*W$22 -> 0.28300146 | W26: =W3*W$23 -> 0.15085227 | X26: =W$24*X3 -> 0.050897476 | AA26: =AA3*AE$19 -> 0.20874704 | AB26: =AB3*AE$20 -> 0.18992087 | AC26: =AC3*AE$21 -> 0.22324751 | AD26: =AD3*AE$22 -> 0.30780053 | AE26: =AE3*AE$23 -> 0.19665759 | AF26: =AE$24*AF3 -> 0.13147919
C27: =C4*G$19 -> 0.11131106 | D27: =D4*G$20 -> 0.11184016 | E27: =E4*G$21 -> 0.098661868 | F27: =F4*G$22 -> 0.098661868 | G27: =G4*G$23 -> 0.14321705 | H27: =G$24*H4 -> 0.11184016 | K27: =K4*O$19 -> 0.14783487 | L27: =L4*O$20 -> 0.10750259 | M27: =M4*O$21 -> 0.068572198 | N27: =N4*O$22 -> 0.11164928 | O27: =O4*O$23 -> 0.13166701 | P27: =O$24*P4 -> 0.082087756 | S27: =S4*W$19 -> 0.30806913 | T27: =T4*W$20 -> 0.30631924 | U27: =U4*W$21 -> 0.3903379 | V27: =V4*W$22 -> 0.42450219 | W27: =W4*W$23 -> 0.25142045 | X27: =W$24*X4 -> 0.30538486 | AA27: =AA4*AE$19 -> 0.18235734 | AB27: =AB4*AE$20 -> 0.16591117 | AC27: =AC4*AE$21 -> 0.14944924 | AD27: =AD4*AE$22 -> 0.17617183 | AE27: =AE4*AE$23 -> 0.17867528 | AF27: =AE$24*AF4 -> 0.14471157
C28: =C5*G$19 -> 0.16696659 | D28: =D5*G$20 -> 0.22368032 | E28: =E5*G$21 -> 0.19732374 | F28: =F5*G$22 -> 0.19732374 | G28: =G5*G$23 -> 0.19095607 | H28: =G$24*H5 -> 0.22368032 | K28: =K5*O$19 -> 0.44350461 | L28: =L5*O$20 -> 0.21500518 | M28: =M5*O$21 -> 0.34286099 | N28: =N5*O$22 -> 0.33494784 | O28: =O5*O$23 -> 0.26333402 | P28: =O$24*P5 -> 0.49252654 | S28: =S5*W$19 -> 0.15403456 | T28: =T5*W$20 -> 0.15315962 | U28: =U5*W$21 -> 0.19516895 | V28: =V5*W$22 -> 0.28300146 | W28: =W5*W$23 -> 0.20113636 | X28: =W$24*X5 -> 0.30538486 | AA28: =AA5*AE$19 -> 0.23895571 | AB28: =AB5*AE$20 -> 0.20903497 | AC28: =AC5*AE$21 -> 0.2555546 | AD28: =AD5*AE$22 -> 0.27965534 | AE28: =AE5*AE$23 -> 0.23001212 | AF28: =AE$24*AF5 -> 0.3313068
C29: =C6*G$19 -> 0.16696659 | D29: =D6*G$20 -> 0.22368032 | E29: =E6*G$21 -> 0.19732374 | F29: =F6*G$22 -> 0.19732374 | G29: =G6*G$23 -> 0.19095607 | H29: =G$24*H6 -> 0.22368032 | K29: =K6*O$19 -> 0.073917435 | L29: =L6*O$20 -> 0.10750259 | M29: =M6*O$21 -> 0.114287 | N29: =N6*O$22 -> 0.11164928 | O29: =O6*O$23 -> 0.13166701 | P29: =O$24*P6 -> 0.12313163 | S29: =S6*W$19 -> 0.077017281 | T29: =T6*W$20 -> 0.10210641 | U29: =U6*W$21 -> 0.097584476 | V29: =V6*W$22 -> 0.14150073 | W29: =W6*W$23 -> 0.10056818 | X29: =W$24*X6 -> 0.45807728 | AA29: =AA6*AE$19 -> 0.10437352 | AB29: =AB6*AE$20 -> 0.14493675 | AC29: =AC6*AE$21 -> 0.14063712 | AD29: =AD6*AE$22 -> 0.15390027 | AE29: =AE6*AE$23 -> 0.14489855 | AF29: =AE$24*AF6 -> 0.23891354
C30: =C7*G$19 -> 0.066786637 | D30: =D7*G$20 -> 0.037280054 | E30: =E7*G$21 -> 0.049330934 | F30: =F7*G$22 -> 0.049330934 | G30: =G7*G$23 -> 0.047739018 | H30: =G$24*H7 -> 0.037280054 | K30: =K7*O$19 -> 0.036958717 | L30: =L7*O$20 -> 0.035834196 | M30: =M7*O$21 -> 0.057143498 | N30: =N7*O$22 -> 0.037216427 | O30: =O7*O$23 -> 0.043889003 | P30: =O$24*P7 -> 0.049252654 | S30: =S7*W$19 -> 0.051344854 | T30: =T7*W$20 -> 0.061263848 | U30: =U7*W$21 -> 0.048792238 | V30: =V7*W$22 -> 0.070750364 | W30: =W7*W$23 -> 0.050284089 | X30: =W$24*X7 -> 0.038173107 | AA30: =AA7*AE$19 -> 0.053321609 | AB30: =AB7*AE$20 -> 0.046644966 | AC30: =AC7*AE$21 -> 0.055811878 | AD30: =AD7*AE$22 -> 0.053354242 | AE30: =AE7*AE$23 -> 0.050233523 | AF30: =AE$24*AF7 -> 0.042313921
C31: =C8*G$19 -> 0.11131106 | D31: =D8*G$20 -> 0.11184016 | E31: =E8*G$21 -> 0.098661868 | F31: =F8*G$22 -> 0.098661868 | G31: =G8*G$23 -> 0.14321705 | H31: =G$24*H8 -> 0.11184016 | K31: =K8*O$19 -> 0.29566974 | L31: =L8*O$20 -> 0.32250777 | M31: =M8*O$21 -> 0.17143049 | N31: =N8*O$22 -> 0.22329856 | O31: =O8*O$23 -> 0.21944501 | P31: =O$24*P8 -> 0.24626327 | S31: =S8*W$19 -> 0.46210369 | T31: =T8*W$20 -> 0.061263848 | U31: =U8*W$21 -> 0.097584476 | V31: =V8*W$22 -> 0.047166909 | W31: =W8*W$23 -> 0.20113636 | X31: =W$24*X8 -> 0.15269243 | AA31: =AA8*AE$19 -> 0.26300479 | AB31: =AB8*AE$20 -> 0.1399349 | AC31: =AC8*AE$21 -> 0.1277773 | AD31: =AD8*AE$22 -> 0.10670848 | AE31: =AE8*AE$23 -> 0.19665759 | AF31: =AE$24*AF8 -> 0.1656534
C34: =SUM(C26:H26) -> 2.0329642 | E34: =G19 -> 0.33393319 | G34: =C34/E34 -> 6.087937 | K34: =SUM(K26:P26) -> 0.89161066 | M34: =O19 -> 0.14783487 | O34: =K34/M34 -> 6.0311256 | S34: =SUM(S26:X26) -> 0.98711434 | U34: =W19 -> 0.15403456 | W34: =S34/U34 -> 6.4083951 | AA34: =SUM(AA26:AF26) -> 1.2578527 | AC34: =AE19 -> 0.20874704 | AE34: =AA34/AC34 -> 6.0257273
C35: =SUM(C27:H27) -> 0.67553218 | E35: =G20 -> 0.11184016 | G35: =C35/E35 -> 6.0401573 | K35: =SUM(K27:P27) -> 0.6493137 | M35: =O20 -> 0.10750259 | O35: =K35/M35 -> 6.039982 | S35: =SUM(S27:X27) -> 1.9860338 | U35: =W20 -> 0.30631924 | W35: =S35/U35 -> 6.4835423 | AA35: =SUM(AA27:AF27) -> 0.99727642 | AC35: =AE20 -> 0.16591117 | AE35: =AA35/AC35 -> 6.010906
C36: =SUM(C28:H28) -> 1.1999308 | E36: =G21 -> 0.19732374 | G36: =C36/E36 -> 6.0810261 | K36: =SUM(K28:P28) -> 2.0921792 | M36: =O21 -> 0.34286099 | O36: =K36/M36 -> 6.1021208 | S36: =SUM(S28:X28) -> 1.2918858 | U36: =W21 -> 0.19516895 | W36: =S36/U36 -> 6.6193203 | AA36: =SUM(AA28:AF28) -> 1.5445195 | AC36: =AE21 -> 0.2555546 | AE36: =AA36/AC36 -> 6.0437946
C37: =SUM(C29:H29) -> 1.1999308 | E37: =G22 -> 0.19732374 | G37: =C37/E37 -> 6.0810261 | K37: =SUM(K29:P29) -> 0.66215494 | M37: =O22 -> 0.11164928 | O37: =K37/M37 -> 5.9306691 | S37: =SUM(S29:X29) -> 0.97685436 | U37: =W22 -> 0.14150073 | W37: =S37/U37 -> 6.9035289 | AA37: =SUM(AA29:AF29) -> 0.92765976 | AC37: =AE22 -> 0.15390027 | AE37: =AA37/AC37 -> 6.0276683
C38: =SUM(C30:H30) -> 0.28774763 | E38: =G23 -> 0.047739018 | G38: =C38/E38 -> 6.0275147 | K38: =SUM(K30:P30) -> 0.2602945 | M38: =O23 -> 0.043889003 | O38: =K38/M38 -> 5.9307453 | S38: =SUM(S30:X30) -> 0.3206085 | U38: =W23 -> 0.050284089 | W38: =S38/U38 -> 6.3759432 | AA38: =SUM(AA30:AF30) -> 0.30168014 | AC38: =AE23 -> 0.050233523 | AE38: =AA38/AC38 -> 6.0055541
C39: =SUM(C31:H31) -> 0.67553218 | E39: =G24 -> 0.11184016 | G39: =C39/E39 -> 6.0401573 | K39: =SUM(K31:P31) -> 1.4786148 | M39: =O24 -> 0.24626327 | O39: =K39/M39 -> 6.0042038 | S39: =SUM(S31:X31) -> 1.0219477 | U39: =W24 -> 0.15269243 | W39: =S39/U39 -> 6.6928512 | AA39: =SUM(AA31:AF31) -> 0.99973647 | AC39: =AE24 -> 0.1656534 | AE39: =AA39/AC39 -> 6.0351099
F41: lambda | G41: =AVERAGE(G34:G39) -> 6.0596364 | N41: lambda | O41: =AVERAGE(O34:O39) -> 6.0064744 | V41: lambda | W41: =AVERAGE(W34:W39) -> 6.5805968 | AD41: lambda | AE41: =AVERAGE(AE34:AE39) -> 6.0247934
F42: CI | G42: =(G41-6)/5 -> 0.011927283 | N42: CI | O42: =(O41-6)/5 -> 0.0012948843 | V42: CI | W42: =(W41-6)/5 -> 0.11611937 | AD42: CI | AE42: =(AE41-6)/5 -> 0.0049586726
F43: CR | G43: =G42/1.24 -> 0.0096187769 | N43: CR | O43: =O42/1.24 -> 0.0010442615 | V43: CR | W43: =W42/1.24 -> 0.093644653 | AD43: CR | AE43: =AE42/1.24 -> 0.0039989295

Sheet PraćenjeIKontorlaProcesa
C3: =B4 -> Svi koraci procesa su digitalno zabilježeni, što omogućuje praćenje statusa certifikata u 100 % slučajeva bez dodatnih provjera. | D3: =B5 -> Digitalni zapisi omogućuju naknadnu provjeru u 90 % kontrola, čime se smanjuje potreba za ponovnim pregledima proizvoda. | E3: =B6 -> Organizatori imaju uvid u prijave, status priprema i povratne informacije u realnom vremenu, što smanjuje kašnjenja i nejasnoće u provedbi za oko 35 %. | H3: =G4 -> Svi koraci procesa su digitalno zabilježeni, što omogućuje praćenje statusa certifikata u 100 % slučajeva bez dodatnih provjera. | I3: =G5 -> Digitalni zapisi omogućuju naknadnu provjeru u 90 % kontrola, čime se smanjuje potreba za ponovnim pregledima proizvoda. | J3: =G6 -> Organizatori imaju uvid u prijave, status priprema i povratne informacije u realnom vremenu, što smanjuje kašnjenja i nejasnoće u provedbi za oko 35 %. | M3: =L4 -> Svi koraci procesa su digitalno zabilježeni, što omogućuje praćenje statusa certifikata u 100 % slučajeva bez dodatnih provjera. | N3: =L5 -> Digitalni zapisi omogućuju naknadnu provjeru u 90 % kontrola, čime se smanjuje potreba za ponovnim pregledima proizvoda. | O3: =L6 -> Organizatori imaju uvid u prijave, status priprema i povratne informacije u realnom vremenu, što smanjuje kašnjenja i nejasnoće u provedbi za oko 35 %. | R3: =Q4 -> Svi koraci procesa su digitalno zabilježeni, što omogućuje praćenje statusa certifikata u 100 % slučajeva bez dodatnih provjera. | S3: =Q5 -> Digitalni zapisi omogućuju naknadnu provjeru u 90 % kontrola, čime se smanjuje potreba za ponovnim pregledima proizvoda. | T3: =Q6 -> Organizatori imaju uvid u prijave, status priprema i povratne informacije u realnom vremenu, što smanjuje kašnjenja i nejasnoće u provedbi za oko 35 %.
B4: Svi koraci procesa su digitalno zabilježeni, što omogućuje praćenje statusa certifikata u 100 % slučajeva bez dodatnih provjera. | C4: 1 | D4: 3 | E4: 5 | G4: =B4 -> Svi koraci procesa su digitalno zabilježeni, što omogućuje praćenje statusa certifikata u 100 % slučajeva bez dodatnih provjera. | H4: 1 | I4: 0.2 | J4: 0.33333333 | L4: =G4 -> Svi koraci procesa su digitalno zabilježeni, što omogućuje praćenje statusa certifikata u 100 % slučajeva bez dodatnih provjera. | M4: 1 | N4: 0.5 | O4: 0.25 | Q4: =L4 -> Svi koraci procesa su digitalno zabilježeni, što omogućuje praćenje statusa certifikata u 100 % slučajeva bez dodatnih provjera. | R4: =GEOMEAN(C4,H4,M4) -> 1 | S4: =GEOMEAN(D4,I4,N4) -> 0.66943295 | T4: =GEOMEAN(E4,J4,O4) -> 0.74690079
B5: Digitalni zapisi omogućuju naknadnu provjeru u 90 % kontrola, čime se smanjuje potreba za ponovnim pregledima proizvoda. | C5: 0.33333333 | D5: 1 | E5: 2 | G5: =B5 -> Digitalni zapisi omogućuju naknadnu provjeru u 90 % kontrola, čime se smanjuje potreba za ponovnim pregledima proizvoda. | H5: 5 | I5: 1 | J5: 3 | L5: =G5 -> Digitalni zapisi omogućuju naknadnu provjeru u 90 % kontrola, čime se smanjuje potreba za ponovnim pregledima proizvoda. | M5: 2 | N5: 1 | O5: 0.33333333 | Q5: =L5 -> Digitalni zapisi omogućuju naknadnu provjeru u 90 % kontrola, čime se smanjuje potreba za ponovnim pregledima proizvoda. | R5: =GEOMEAN(C5,H5,M5) -> 1.4938016 | S5: =GEOMEAN(D5,I5,N5) -> 1 | T5: =GEOMEAN(E5,J5,O5) -> 1.259921
B6: Organizatori imaju uvid u prijave, status priprema i povratne informacije u realnom vremenu, što smanjuje kašnjenja i nejasnoće u provedbi za oko 35 %. | C6: 0.2 | D6: 0.5 | E6: 1 | G6: =B6 -> Organizatori imaju uvid u prijave, status priprema i povratne informacije u realnom vremenu, što smanjuje kašnjenja i nejasnoće u provedbi za oko 35 %. | H6: 3 | I6: 0.33333333 | J6: 1 | L6: =G6 -> Organizatori imaju uvid u prijave, status priprema i povratne informacije u realnom vremenu, što smanjuje kašnjenja i nejasnoće u provedbi za oko 35 %. | M6: 4 | N6: 3 | O6: 1 | Q6: =L6 -> Organizatori imaju uvid u prijave, status priprema i povratne informacije u realnom vremenu, što smanjuje kašnjenja i nejasnoće u provedbi za oko 35 %. | R6: =GEOMEAN(C6,H6,M6) -> 1.3388659 | S6: =GEOMEAN(D6,I6,N6) -> 0.79370053 | T6: =GEOMEAN(E6,J6,O6) -> 1
C8: =SUM(C4:C6) -> 1.5333333 | D8: =SUM(D4:D6) -> 4.5 | E8: =SUM(E4:E6) -> 8 | H8: =SUM(H4:H6) -> 9 | I8: =SUM(I4:I6) -> 1.5333333 | J8: =SUM(J4:J6) -> 4.3333333 | M8: =SUM(M4:M6) -> 7 | N8: =SUM(N4:N6) -> 4.5 | O8: =SUM(O4:O6) -> 1.5833333 | R8: =SUM(R4:R6) -> 3.8326675 | S8: =SUM(S4:S6) -> 2.4631335 | T8: =SUM(T4:T6) -> 3.0068218
C11: =C4/C$8 -> 0.65217391 | D11: =D4/D$8 -> 0.66666667 | E11: =E4/E$8 -> 0.625 | H11: =H4/H$8 -> 0.11111111 | I11: =I4/I$8 -> 0.13043478 | J11: =J4/J$8 -> 0.076923077 | M11: =M4/M$8 -> 0.14285714 | N11: =N4/N$8 -> 0.11111111 | O11: =O4/O$8 -> 0.15789474 | R11: =R4/R$8 -> 0.26091489 | S11: =S4/S$8 -> 0.27178103 | T11: =T4/T$8 -> 0.24840208
C12: =C5/C$8 -> 0.2173913 | D12: =D5/D$8 -> 0.22222222 | E12: =E5/E$8 -> 0.25 | H12: =H5/H$8 -> 0.55555556 | I12: =I5/I$8 -> 0.65217391 | J12: =J5/J$8 -> 0.69230769 | M12: =M5/M$8 -> 0.28571429 | N12: =N5/N$8 -> 0.22222222 | O12: =O5/O$8 -> 0.21052632 | R12: =R5/R$8 -> 0.38975507 | S12: =S5/S$8 -> 0.40598693 | T12: =T5/T$8 -> 0.41902085
C13: =C6/C$8 -> 0.13043478 | D13: =D6/D$8 -> 0.11111111 | E13: =E6/E$8 -> 0.125 | H13: =H6/H$8 -> 0.33333333 | I13: =I6/I$8 -> 0.2173913 | J13: =J6/J$8 -> 0.23076923 | M13: =M6/M$8 -> 0.57142857 | N13: =N6/N$8 -> 0.66666667 | O13: =O6/O$8 -> 0.63157895 | R13: =R6/R$8 -> 0.34933004 | S13: =S6/S$8 -> 0.32223204 | T13: =T6/T$8 -> 0.33257707
D15: =B4 -> Svi koraci procesa su digitalno zabilježeni, što omogućuje praćenje statusa certifikata u 100 % slučajeva bez dodatnih provjera. | E15: =AVERAGE(C11:E11) -> 0.64794686 | I15: =G4 -> Svi koraci procesa su digitalno zabilježeni, što omogućuje praćenje statusa certifikata u 100 % slučajeva bez dodatnih provjera. | J15: =AVERAGE(H11:J11) -> 0.10615632 | N15: =L4 -> Svi koraci procesa su digitalno zabilježeni, što omogućuje praćenje statusa certifikata u 100 % slučajeva bez dodatnih provjera. | O15: =AVERAGE(M11:O11) -> 0.13728766 | S15: =Q4 -> Svi koraci procesa su digitalno zabilježeni, što omogućuje praćenje statusa certifikata u 100 % slučajeva bez dodatnih provjera. | T15: =AVERAGE(R11:T11) -> 0.260366
D16: =B5 -> Digitalni zapisi omogućuju naknadnu provjeru u 90 % kontrola, čime se smanjuje potreba za ponovnim pregledima proizvoda. | E16: =AVERAGE(C12:E12) -> 0.22987118 | I16: =G5 -> Digitalni zapisi omogućuju naknadnu provjeru u 90 % kontrola, čime se smanjuje potreba za ponovnim pregledima proizvoda. | J16: =AVERAGE(H12:J12) -> 0.63334572 | N16: =L5 -> Digitalni zapisi omogućuju naknadnu provjeru u 90 % kontrola, čime se smanjuje potreba za ponovnim pregledima proizvoda. | O16: =AVERAGE(M12:O12) -> 0.23948761 | S16: =Q5 -> Digitalni zapisi omogućuju naknadnu provjeru u 90 % kontrola, čime se smanjuje potreba za ponovnim pregledima proizvoda. | T16: =AVERAGE(R12:T12) -> 0.40492095
D17: =B6 -> Organizatori imaju uvid u prijave, status priprema i povratne informacije u realnom vremenu, što smanjuje kašnjenja i nejasnoće u provedbi za oko 35 %. | E17: =AVERAGE(C13:E13) -> 0.12218196 | I17: =G6 -> Organizatori imaju uvid u prijave, status priprema i povratne informacije u realnom vremenu, što smanjuje kašnjenja i nejasnoće u provedbi za oko 35 %. | J17: =AVERAGE(H13:J13) -> 0.26049796 | N17: =L6 -> Organizatori imaju uvid u prijave, status priprema i povratne informacije u realnom vremenu, što smanjuje kašnjenja i nejasnoće u provedbi za oko 35 %. | O17: =AVERAGE(M13:O13) -> 0.62322473 | S17: =Q6 -> Organizatori imaju uvid u prijave, status priprema i povratne informacije u realnom vremenu, što smanjuje kašnjenja i nejasnoće u provedbi za oko 35 %. | T17: =AVERAGE(R13:T13) -> 0.33471305
B19: konzistentnost | G19: konzistentnost | L19: konzistentnost | Q19: konzistentnost
C21: =C4*E$15 -> 0.64794686 | D21: =D4*E$16 -> 0.68961353 | E21: =E4*E$17 -> 0.61090982 | H21: =H4*J$15 -> 0.10615632 | I21: =I4*J$16 -> 0.12666914 | J21: =J4*J$17 -> 0.086832652 | M21: =M4*O$15 -> 0.13728766 | N21: =N4*O$16 -> 0.1197438 | O21: =O4*O$17 -> 0.15580618 | R21: =R4*T$15 -> 0.260366 | S21: =S4*T$16 -> 0.27106743 | T21: =T4*T$17 -> 0.24999744
C22: =C5*E$15 -> 0.21598229 | D22: =D5*E$16 -> 0.22987118 | E22: =E5*E$17 -> 0.24436393 | H22: =H5*J$15 -> 0.53078162 | I22: =I5*J$16 -> 0.63334572 | J22: =J5*J$17 -> 0.78149387 | M22: =M5*O$15 -> 0.27457533 | N22: =N5*O$16 -> 0.23948761 | O22: =O5*O$17 -> 0.20774158 | R22: =R5*T$15 -> 0.38893514 | S22: =S5*T$16 -> 0.40492095 | T22: =T5*T$17 -> 0.42171202
C23: =C6*E$15 -> 0.12958937 | D23: =D6*E$16 -> 0.11493559 | E23: =E6*E$17 -> 0.12218196 | H23: =H6*J$15 -> 0.31846897 | I23: =I6*J$16 -> 0.21111524 | J23: =J6*J$17 -> 0.26049796 | M23: =M6*O$15 -> 0.54915065 | N23: =N6*O$16 -> 0.71846282 | O23: =O6*O$17 -> 0.62322473 | R23: =R6*T$15 -> 0.34859516 | S23: =S6*T$16 -> 0.32138597 | T23: =T6*T$17 -> 0.33471305
C25: =SUM(C21:E21) -> 1.9484702 | D25: =SUM(C22:E22) -> 0.69021739 | E25: =SUM(C23:E23) -> 0.36670692 | H25: =SUM(H21:J21) -> 0.31965812 | I25: =SUM(H22:J22) -> 1.9456212 | J25: =SUM(H23:J23) -> 0.79008217 | M25: =SUM(M21:O21) -> 0.41283765 | N25: =SUM(M22:O22) -> 0.72180451 | O25: =SUM(M23:O23) -> 1.8908382 | R25: =SUM(R21:T21) -> 0.78143087 | S25: =SUM(R22:T22) -> 1.2155681 | T25: =SUM(R23:T23) -> 1.0046942
C27: =E15 -> 0.64794686 | D27: =E16 -> 0.22987118 | E27: =E17 -> 0.12218196 | H27: =J15 -> 0.10615632 | I27: =J16 -> 0.63334572 | J27: =J17 -> 0.26049796 | M27: =O15 -> 0.13728766 | N27: =O16 -> 0.23948761 | O27: =O17 -> 0.62322473 | R27: =T15 -> 0.260366 | S27: =T16 -> 0.40492095 | T27: =T17 -> 0.33471305
C29: =C25/C27 -> 3.0071451 | D29: =D25/D27 -> 3.002627 | E29: =E25/E27 -> 3.001318 | H29: =H25/H27 -> 3.0112019 | I29: =I25/I27 -> 3.0719734 | J29: =J25/J27 -> 3.0329688 | M29: =M25/M27 -> 3.0070994 | N29: =N25/N27 -> 3.0139535 | O29: =O25/O27 -> 3.0339589 | R29: =R25/R27 -> 3.0012785 | S29: =S25/S27 -> 3.0019887 | T29: =T25/T27 -> 3.0016582
D31: lambda | E31: =AVERAGE(C29:E29) -> 3.0036967 | I31: lambda | J31: =AVERAGE(H29:J29) -> 3.0387147 | N31: lambda | O31: =AVERAGE(M29:O29) -> 3.0183373 | S31: lambda | T31: =AVERAGE(R29:T29) -> 3.0016418
D32: CI | E32: =(E31-3)/2 -> 0.0018483339 | I32: CI | J32: =(J31-3)/2 -> 0.01935734 | N32: CI | O32: =(O31-3)/2 -> 0.0091686286 | S32: CI | T32: =(T31-3)/2 -> 0.00082089543
D33: CR | E33: =E32/0.52 -> 0.0035544883 | I33: CR | J33: =J32/0.52 -> 0.037225655 | N33: CR | O33: =O32/0.52 -> 0.017631978 | S33: CR | T33: =T32/0.52 -> 0.0015786451

Sheet AdministrativnoOpterećenje
C3: =B4 -> Automatsko izdavanje certifikata i digitalna dokumentacija smanjuju administrativne zadatke zaposlenika za oko 60 % u odnosu na ručni postupak. | D3: =B5 -> Uklanjanjem ručnih izvještaja i priprema za terenske kontrole, administrativno opterećenje zaposlenika smanjuje se za približno 40 %. | E3: =B6 -> Digitalna evidencija sudionika i automatizirani obrasci smanjuju administrativne zadatke u fazi pripreme za približno 30 %, iako provedba aktivnosti ostaje fizička. | H3: =G4 -> Automatsko izdavanje certifikata i digitalna dokumentacija smanjuju administrativne zadatke zaposlenika za oko 60 % u odnosu na ručni postupak. | I3: =G5 -> Uklanjanjem ručnih izvještaja i priprema za terenske kontrole, administrativno opterećenje zaposlenika smanjuje se za približno 40 %. | J3: =G6 -> Digitalna evidencija sudionika i automatizirani obrasci smanjuju administrativne zadatke u fazi pripreme za približno 30 %, iako provedba aktivnosti ostaje fizička. | M3: =L4 -> Automatsko izdavanje certifikata i digitalna dokumentacija smanjuju administrativne zadatke zaposlenika za oko 60 % u odnosu na ručni postupak. | N3: =L5 -> Uklanjanjem ručnih izvještaja i priprema za terenske kontrole, administrativno opterećenje zaposlenika smanjuje se za približno 40 %. | O3: =L6 -> Digitalna evidencija sudionika i automatizirani obrasci smanjuju administrativne zadatke u fazi pripreme za približno 30 %, iako provedba aktivnosti ostaje fizička. | R3: =Q4 -> Automatsko izdavanje certifikata i digitalna dokumentacija smanjuju administrativne zadatke zaposlenika za oko 60 % u odnosu na ručni postupak. | S3: =Q5 -> Uklanjanjem ručnih izvještaja i priprema za terenske kontrole, administrativno opterećenje zaposlenika smanjuje se za približno 40 %. | T3: =Q6 -> Digitalna evidencija sudionika i automatizirani obrasci smanjuju administrativne zadatke u fazi pripreme za približno 30 %, iako provedba aktivnosti ostaje fizička.
B4: Automatsko izdavanje certifikata i digitalna dokumentacija smanjuju administrativne zadatke zaposlenika za oko 60 % u odnosu na ručni postupak. | C4: 1 | D4: 2 | E4: 4 | G4: =B4 -> Automatsko izdavanje certifikata i digitalna dokumentacija smanjuju administrativne zadatke zaposlenika za oko 60 % u odnosu na ručni postupak. | H4: 1 | I4: 1 | J4: 5 | L4: =G4 -> Automatsko izdavanje certifikata i digitalna dokumentacija smanjuju administrativne zadatke zaposlenika za oko 60 % u odnosu na ručni postupak. | M4: 1 | N4: 3 | O4: 5 | Q4: =L4 -> Automatsko izdavanje certifikata i digitalna dokumentacija smanjuju administrativne zadatke zaposlenika za oko 60 % u odnosu na ručni postupak. | R4: =GEOMEAN(C4,H4,M4) -> 1 | S4: =GEOMEAN(D4,I4,N4) -> 1.8171206 | T4: =GEOMEAN(E4,J4,O4) -> 4.6415888
B5: Uklanjanjem ručnih izvještaja i priprema za terenske kontrole, administrativno opterećenje zaposlenika smanjuje se za približno 40 %. | C5: 0.5 | D5: 1 | E5: 2 | G5: =B5 -> Uklanjanjem ručnih izvještaja i priprema za terenske kontrole, administrativno opterećenje zaposlenika smanjuje se za približno 40 %. | H5: 1 | I5: 1 | J5: 5 | L5: =G5 -> Uklanjanjem ručnih izvještaja i priprema za terenske kontrole, administrativno opterećenje zaposlenika smanjuje se za približno 40 %. | M5: 0.33333333 | N5: 1 | O5: 2 | Q5: =L5 -> Uklanjanjem ručnih izvještaja i priprema za terenske kontrole, administrativno opterećenje zaposlenika smanjuje se za približno 40 %. | R5: =GEOMEAN(C5,H5,M5) -> 0.55032121 | S5: =GEOMEAN(D5,I5,N5) -> 1 | T5: =GEOMEAN(E5,J5,O5) -> 2.7144176
B6: Digitalna evidencija sudionika i automatizirani obrasci smanjuju administrativne zadatke u fazi pripreme za približno 30 %, iako provedba aktivnosti ostaje fizička. | C6: 0.25 | D6: 0.5 | E6: 1 | G6: =B6 -> Digitalna evidencija sudionika i automatizirani obrasci smanjuju administrativne zadatke u fazi pripreme za približno 30 %, iako provedba aktivnosti ostaje fizička. | H6: 0.2 | I6: 0.2 | J6: 1 | L6: =G6 -> Digitalna evidencija sudionika i automatizirani obrasci smanjuju administrativne zadatke u fazi pripreme za približno 30 %, iako provedba aktivnosti ostaje fizička. | M6: 0.2 | N6: 0.5 | O6: 1 | Q6: =L6 -> Digitalna evidencija sudionika i automatizirani obrasci smanjuju administrativne zadatke u fazi pripreme za približno 30 %, iako provedba aktivnosti ostaje fizička. | R6: =GEOMEAN(C6,H6,M6) -> 0.21544347 | S6: =GEOMEAN(D6,I6,N6) -> 0.36840315 | T6: =GEOMEAN(E6,J6,O6) -> 1
C8: =SUM(C4:C6) -> 1.75 | D8: =SUM(D4:D6) -> 3.5 | E8: =SUM(E4:E6) -> 7 | H8: =SUM(H4:H6) -> 2.2 | I8: =SUM(I4:I6) -> 2.2 | J8: =SUM(J4:J6) -> 11 | M8: =SUM(M4:M6) -> 1.5333333 | N8: =SUM(N4:N6) -> 4.5 | O8: =SUM(O4:O6) -> 8 | R8: =SUM(R4:R6) -> 1.7657647 | S8: =SUM(S4:S6) -> 3.1855237 | T8: =SUM(T4:T6) -> 8.3560065
C11: =C4/C$8 -> 0.57142857 | D11: =D4/D$8 -> 0.57142857 | E11: =E4/E$8 -> 0.57142857 | H11: =H4/H$8 -> 0.45454545 | I11: =I4/I$8 -> 0.45454545 | J11: =J4/J$8 -> 0.45454545 | M11: =M4/M$8 -> 0.65217391 | N11: =N4/N$8 -> 0.66666667 | O11: =O4/O$8 -> 0.625 | R11: =R4/R$8 -> 0.56632688 | S11: =S4/S$8 -> 0.57043072 | T11: =T4/T$8 -> 0.55547933
C12: =C5/C$8 -> 0.28571429 | D12: =D5/D$8 -> 0.28571429 | E12: =E5/E$8 -> 0.28571429 | H12: =H5/H$8 -> 0.45454545 | I12: =I5/I$8 -> 0.45454545 | J12: =J5/J$8 -> 0.45454545 | M12: =M5/M$8 -> 0.2173913 | N12: =N5/N$8 -> 0.22222222 | O12: =O5/O$8 -> 0.25 | R12: =R5/R$8 -> 0.31166169 | S12: =S5/S$8 -> 0.31392012 | T12: =T5/T$8 -> 0.32484628
C13: =C6/C$8 -> 0.14285714 | D13: =D6/D$8 -> 0.14285714 | E13: =E6/E$8 -> 0.14285714 | H13: =H6/H$8 -> 0.090909091 | I13: =I6/I$8 -> 0.090909091 | J13: =J6/J$8 -> 0.090909091 | M13: =M6/M$8 -> 0.13043478 | N13: =N6/N$8 -> 0.11111111 | O13: =O6/O$8 -> 0.125 | R13: =R6/R$8 -> 0.12201143 | S13: =S6/S$8 -> 0.11564916 | T13: =T6/T$8 -> 0.11967439
D15: =B4 -> Automatsko izdavanje certifikata i digitalna dokumentacija smanjuju administrativne zadatke zaposlenika za oko 60 % u odnosu na ručni postupak. | E15: =AVERAGE(C11:E11) -> 0.57142857 | I15: =G4 -> Automatsko izdavanje certifikata i digitalna dokumentacija smanjuju administrativne zadatke zaposlenika za oko 60 % u odnosu na ručni postupak. | J15: =AVERAGE(H11:J11) -> 0.45454545 | N15: =L4 -> Automatsko izdavanje certifikata i digitalna dokumentacija smanjuju administrativne zadatke zaposlenika za oko 60 % u odnosu na ručni postupak. | O15: =AVERAGE(M11:O11) -> 0.64794686 | S15: =Q4 -> Automatsko izdavanje certifikata i digitalna dokumentacija smanjuju administrativne zadatke zaposlenika za oko 60 % u odnosu na ručni postupak. | T15: =AVERAGE(R11:T11) -> 0.56407897
D16: =B5 -> Uklanjanjem ručnih izvještaja i priprema za terenske kontrole, administrativno opterećenje zaposlenika smanjuje se za približno 40 %. | E16: =AVERAGE(C12:E12) -> 0.28571429 | I16: =G5 -> Uklanjanjem ručnih izvještaja i priprema za terenske kontrole, administrativno opterećenje zaposlenika smanjuje se za približno 40 %. | J16: =AVERAGE(H12:J12) -> 0.45454545 | N16: =L5 -> Uklanjanjem ručnih izvještaja i priprema za terenske kontrole, administrativno opterećenje zaposlenika smanjuje se za približno 40 %. | O16: =AVERAGE(M12:O12) -> 0.22987118 | S16: =Q5 -> Uklanjanjem ručnih izvještaja i priprema za terenske kontrole, administrativno opterećenje zaposlenika smanjuje se za približno 40 %. | T16: =AVERAGE(R12:T12) -> 0.31680936
D17: =B6 -> Digitalna evidencija sudionika i automatizirani obrasci smanjuju administrativne zadatke u fazi pripreme za približno 30 %, iako provedba aktivnosti ostaje fizička. | E17: =AVERAGE(C13:E13) -> 0.14285714 | I17: =G6 -> Digitalna evidencija sudionika i automatizirani obrasci smanjuju administrativne zadatke u fazi pripreme za približno 30 %, iako provedba aktivnosti ostaje fizička. | J17: =AVERAGE(H13:J13) -> 0.090909091 | N17: =L6 -> Digitalna evidencija sudionika i automatizirani obrasci smanjuju administrativne zadatke u fazi pripreme za približno 30 %, iako provedba aktivnosti ostaje fizička. | O17: =AVERAGE(M13:O13) -> 0.12218196 | S17: =Q6 -> Digitalna evidencija sudionika i automatizirani obrasci smanjuju administrativne zadatke u fazi pripreme za približno 30 %, iako provedba aktivnosti ostaje fizička. | T17: =AVERAGE(R13:T13) -> 0.11911166
B19: konzistentnost | G19: konzistentnost | L19: konzistentnost | Q19: konzistentnost
C21: =C4*E$15 -> 0.57142857 | D21: =D4*E$16 -> 0.57142857 | E21: =E4*E$17 -> 0.57142857 | H21: =H4*J$15 -> 0.45454545 | I21: =I4*J$16 -> 0.45454545 | J21: =J4*J$17 -> 0.45454545 | M21: =M4*O$15 -> 0.64794686 | N21: =N4*O$16 -> 0.68961353 | O21: =O4*O$17 -> 0.61090982 | R21: =R4*T$15 -> 0.56407897 | S21: =S4*T$16 -> 0.57568082 | T21: =T4*T$17 -> 0.55286735
C22: =C5*E$15 -> 0.28571429 | D22: =D5*E$16 -> 0.28571429 | E22: =E5*E$17 -> 0.28571429 | H22: =H5*J$15 -> 0.45454545 | I22: =I5*J$16 -> 0.45454545 | J22: =J5*J$17 -> 0.45454545 | M22: =M5*O$15 -> 0.21598229 | N22: =N5*O$16 -> 0.22987118 | O22: =O5*O$17 -> 0.24436393 | R22: =R5*T$15 -> 0.31042462 | S22: =S5*T$16 -> 0.31680936 | T22: =T5*T$17 -> 0.32331879
C23: =C6*E$15 -> 0.14285714 | D23: =D6*E$16 -> 0.14285714 | E23: =E6*E$17 -> 0.14285714 | H23: =H6*J$15 -> 0.090909091 | I23: =I6*J$16 -> 0.090909091 | J23: =J6*J$17 -> 0.090909091 | M23: =M6*O$15 -> 0.12958937 | N23: =N6*O$16 -> 0.11493559 | O23: =O6*O$17 -> 0.12218196 | R23: =R6*T$15 -> 0.12152713 | S23: =S6*T$16 -> 0.11671357 | T23: =T6*T$17 -> 0.11911166
C25: =SUM(C21:E21) -> 1.7142857 | D25: =SUM(C22:E22) -> 0.85714286 | E25: =SUM(C23:E23) -> 0.42857143 | H25: =SUM(H21:J21) -> 1.3636364 | I25: =SUM(H22:J22) -> 1.3636364 | J25: =SUM(H23:J23) -> 0.27272727 | M25: =SUM(M21:O21) -> 1.9484702 | N25: =SUM(M22:O22) -> 0.69021739 | O25: =SUM(M23:O23) -> 0.36670692 | R25: =SUM(R21:T21) -> 1.6926271 | S25: =SUM(R22:T22) -> 0.95055278 | T25: =SUM(R23:T23) -> 0.35735236
C27: =E15 -> 0.57142857 | D27: =E16 -> 0.28571429 | E27: =E17 -> 0.14285714 | H27: =J15 -> 0.45454545 | I27: =J16 -> 0.45454545 | J27: =J17 -> 0.090909091 | M27: =O15 -> 0.64794686 | N27: =O16 -> 0.22987118 | O27: =O17 -> 0.12218196 | R27: =T15 -> 0.56407897 | S27: =T16 -> 0.31680936 | T27: =T17 -> 0.11911166
C29: =C25/C27 -> 3 | D29: =D25/D27 -> 3 | E29: =E25/E27 -> 3 | H29: =H25/H27 -> 3 | I29: =I25/I27 -> 3 | J29: =J25/J27 -> 3 | M29: =M25/M27 -> 3.0071451 | N29: =N25/N27 -> 3.002627 | O29: =O25/O27 -> 3.001318 | R29: =R25/R27 -> 3.0006918 | S29: =S25/S27 -> 3.0003936 | T29: =T25/T27 -> 3.0001459
D31: lambda | E31: =AVERAGE(C29:E29) -> 3 | I31: lambda | J31: =AVERAGE(H29:J29) -> 3 | N31: lambda | O31: =AVERAGE(M29:O29) -> 3.0036967 | S31: lambda | T31: =AVERAGE(R29:T29) -> 3.0004104
D32: CI | E32: =(E31-3)/2 -> 0 | I32: CI | J32: =(J31-3)/2 -> 0 | N32: CI | O32: =(O31-3)/2 -> 0.0018483339 | S32: CI | T32: =(T31-3)/2 -> 0.0002052076
D33: CR | E33: =E32/0.52 -> 0 | I33: CR | J33: =J32/0.52 -> 0 | N33: CR | O33: =O32/0.52 -> 0.0035544883 | S33: CR | T33: =T32/0.52 -> 0.00039463

Sheet KoordinacijaIzmeđuOdjela
